<?xml version="1.0" ?>
<!-- =================================================================================== -->
<!-- |    This document was autogenerated by xacro from src/mycobot_ros2/mycobot_gazebo/urdf/ros2_control/gazebo/mycobot_280.urdf.xacro | -->
<!-- |    EDITING THIS FILE BY HAND IS NOT RECOMMENDED   
    <hardware>
      <plugin>gz_ros2_control/GazeboSimSystem</plugin>
    </hardware>                              | -->
<!-- =================================================================================== -->
<robot name="mycobot_280">
  <ros2_control name="RobotSystem" type="system">
    <hardware>
      <plugin>mycobot_hardware/MyCobotHardware</plugin>
    </hardware>
    <joint name="link1_to_link2">
      <command_interface name="position">
        <param name="min">-2.879793</param>
        <param name="max">2.879793</param>
      </command_interface>
      <state_interface name="position"/>
    </joint>
    <joint name="link2_to_link3">
      <command_interface name="position">
        <param name="min">-2.879793</param>
        <param name="max">2.879793</param>
      </command_interface>
      <state_interface name="position"/>
    </joint>
    <joint name="link3_to_link4">
      <command_interface name="position">
        <param name="min">-2.879793</param>
        <param name="max">2.879793</param>
      </command_interface>
      <state_interface name="position"/>
    </joint>
    <joint name="link4_to_link5">
      <command_interface name="position">
        <param name="min">-2.879793</param>
        <param name="max">2.879793</param>
      </command_interface>
      <state_interface name="position"/>
    </joint>
    <joint name="link5_to_link6">
      <command_interface name="position">
        <param name="min">-2.879793</param>
        <param name="max">2.879793</param>
      </command_interface>
      <state_interface name="position"/>
    </joint>
    <joint name="link6_to_link6flange">
      <command_interface name="position">
        <param name="min">-3.05</param>
        <param name="max">3.05</param>
      </command_interface>
      <state_interface name="position"/>
    </joint>
    <joint name="gripper_controller">
      <command_interface name="position">
        <param name="min">-0.7</param>
        <param name="max">0.15</param>
      </command_interface>
      <state_interface name="position"/>
      <state_interface name="velocity"/>
    </joint>
    <joint name="gripper_base_to_gripper_left2">
      <param name="mimic">gripper_controller</param>
      <param name="multiplier">1.0</param>
      <command_interface name="position">
        <param name="min">-0.8</param>
        <param name="max">0.5</param>
      </command_interface>
      <state_interface name="position"/>
      <state_interface name="velocity"/>
    </joint>
    <joint name="gripper_left3_to_gripper_left1">
      <param name="mimic">gripper_controller</param>
      <param name="multiplier">-1.0</param>
      <command_interface name="position">
        <param name="min">-0.5</param>
        <param name="max">0.5</param>
      </command_interface>
      <state_interface name="position"/>
      <state_interface name="velocity"/>
    </joint>
    <joint name="gripper_base_to_gripper_right3">
      <param name="mimic">gripper_controller</param>
      <param name="multiplier">-1.0</param>
      <command_interface name="position">
        <param name="min">-0.15</param>
        <param name="max">0.7</param>
      </command_interface>
      <state_interface name="position"/>
      <state_interface name="velocity"/>
    </joint>
    <joint name="gripper_base_to_gripper_right2">
      <param name="mimic">gripper_controller</param>
      <param name="multiplier">-1.0</param>
      <command_interface name="position">
        <param name="min">-0.5</param>
        <param name="max">0.8</param>
      </command_interface>
      <state_interface name="position"/>
      <state_interface name="velocity"/>
    </joint>
    <joint name="gripper_right3_to_gripper_right1">
      <param name="mimic">gripper_controller</param>
      <param name="multiplier">1.0</param>
      <command_interface name="position">
        <param name="min">-0.5</param>
        <param name="max">0.5</param>
      </command_interface>
      <state_interface name="position"/>
      <state_interface name="velocity"/>
    </joint>
  </ros2_control>
  <link name="world"/>
  <link name="base_link">
    <inertial>
      <origin rpy="0 0 0" xyz="0 0 0.0"/>
      <mass value="0.33"/>
      <inertia ixx="0.000784" ixy="0.0" ixz="0.0" iyy="0.000867" iyz="0.0" izz="0.001598"/>
    </inertial>
    <visual>
      <geometry>
        <mesh filename="file:///home/rosdev/arm_ws/install/mycobot_description/share/mycobot_description/meshes/mycobot_280/base_link.dae"/>
      </geometry>
      <origin rpy="0 0 1.5707963267948966" xyz="0.0 0 -0.03"/>
    </visual>
    <collision>
      <geometry>
        <box size="0.105 0.14 0.02"/>
      </geometry>
      <origin rpy="0 0 0" xyz="0.0 0 -0.015"/>
    </collision>
  </link>
  <link name="link1">
    <inertial>
      <origin rpy="0 0 0" xyz="0 0 0.0"/>
      <mass value="0.12"/>
      <inertia ixx="0.000148" ixy="0.0" ixz="0.0" iyy="0.000148" iyz="0.0" izz="0.000096"/>
    </inertial>
    <visual>
      <geometry>
        <mesh filename="file:///home/rosdev/arm_ws/install/mycobot_description/share/mycobot_description/meshes/mycobot_280/link1.dae"/>
      </geometry>
      <origin rpy=" 0 0 -1.5707963267948966" xyz="0.0 0 0 "/>
    </visual>
    <collision>
      <geometry>
        <box size="0.08 0.12 0.075"/>
      </geometry>
      <origin rpy=" 0 0 0" xyz="0.0 -0.01 0.034"/>
    </collision>
  </link>
  <link name="link2">
    <inertial>
      <origin rpy="0 0 0" xyz="0 0 0.0"/>
      <mass value="0.19"/>
      <inertia ixx="0.000148" ixy="0.0" ixz="0.0" iyy="0.000148" iyz="0.0" izz="0.000096"/>
    </inertial>
    <visual>
      <geometry>
        <mesh filename="file:///home/rosdev/arm_ws/install/mycobot_description/share/mycobot_description/meshes/mycobot_280/link2.dae"/>
      </geometry>
      <origin rpy=" 0 0 -1.5707963267948966" xyz="0.0 0 -0.06096"/>
    </visual>
    <collision>
      <geometry>
        <cylinder length="0.085" radius="0.025"/>
      </geometry>
      <origin rpy=" 0 0 -1.5707963267948966" xyz="0.0 0 -0.02"/>
    </collision>
  </link>
  <link name="link3">
    <inertial>
      <origin rpy="0 0 0" xyz="0 0 0.0"/>
      <mass value="0.16"/>
      <inertia ixx="0.000148" ixy="0.0" ixz="0.0" iyy="0.000148" iyz="0.0" izz="0.000096"/>
    </inertial>
    <visual>
      <geometry>
        <mesh filename="file:///home/rosdev/arm_ws/install/mycobot_description/share/mycobot_description/meshes/mycobot_280/link3.dae"/>
      </geometry>
      <origin rpy=" 0 -1.5707963267948966 0" xyz="0.0 0 0.03256 "/>
    </visual>
    <collision>
      <geometry>
        <cylinder length="0.15" radius="0.025"/>
      </geometry>
      <origin rpy="0 -1.5707963267948966 0" xyz="-0.058 0 0.059"/>
    </collision>
  </link>
  <link name="link4">
    <inertial>
      <origin rpy="0 0 0" xyz="0 0 0.0"/>
      <mass value="0.124"/>
      <inertia ixx="0.000103" ixy="0.0" ixz="0.0" iyy="0.000103" iyz="0.0" izz="0.000096"/>
    </inertial>
    <visual>
      <geometry>
        <mesh filename="file:///home/rosdev/arm_ws/install/mycobot_description/share/mycobot_description/meshes/mycobot_280/link4.dae"/>
      </geometry>
      <origin rpy=" 0 -1.5707963267948966 0" xyz="0.0 0 0.03056 "/>
    </visual>
    <collision>
      <geometry>
        <cylinder length="0.125" radius="0.025"/>
      </geometry>
      <origin rpy="0 -1.5707963267948966 0" xyz="-0.05 0 0.0"/>
    </collision>
  </link>
  <link name="link5">
    <inertial>
      <origin rpy="0 0 0" xyz="0 0 0.0"/>
      <mass value="0.11"/>
      <inertia ixx="0.000103" ixy="0.0" ixz="0.0" iyy="0.000103" iyz="0.0" izz="0.000096"/>
    </inertial>
    <visual>
      <geometry>
        <mesh filename="file:///home/rosdev/arm_ws/install/mycobot_description/share/mycobot_description/meshes/mycobot_280/link5.dae"/>
      </geometry>
      <origin rpy="-1.5707963267948966 0 0" xyz="0.0 0 -0.03356 "/>
    </visual>
    <collision>
      <geometry>
        <box size="0.03 0.035 0.05"/>
      </geometry>
      <origin rpy="0 0.0 0" xyz="0.0 0 -0.005"/>
    </collision>
  </link>
  <link name="link6">
    <inertial>
      <origin rpy="0 0 0" xyz="0 0 0.0"/>
      <mass value="0.0739"/>
      <inertia ixx="0.00006649" ixy="0.0" ixz="0.0" iyy="0.00006649" iyz="0.0" izz="0.000096"/>
    </inertial>
    <visual>
      <geometry>
        <mesh filename="file:///home/rosdev/arm_ws/install/mycobot_description/share/mycobot_description/meshes/mycobot_280/link6.dae"/>
      </geometry>
      <origin rpy="0 0 0" xyz="0 0.00 -0.038"/>
    </visual>
    <collision>
      <geometry>
        <cylinder length="0.06" radius="0.025"/>
      </geometry>
      <origin rpy="-1.5707963267948966 0 0" xyz="0 0.00 0.0"/>
    </collision>
  </link>
  <link name="link6_flange">
    <inertial>
      <origin rpy="0 0 0" xyz="0 0 0.0"/>
      <mass value="0.035"/>
      <inertia ixx="0.0000149" ixy="0.0" ixz="0.0" iyy="0.0000149" iyz="0.0" izz="0.0000196"/>
    </inertial>
    <visual>
      <geometry>
        <mesh filename="file:///home/rosdev/arm_ws/install/mycobot_description/share/mycobot_description/meshes/mycobot_280/link7.dae"/>
      </geometry>
      <origin rpy="0 0 0" xyz="0.0 0 -0.012 "/>
    </visual>
    <collision>
      <geometry>
        <cylinder length="0.02" radius="0.02"/>
      </geometry>
      <origin rpy="0 0 0" xyz="0 0.00 0.0"/>
    </collision>
  </link>
  <link name="gripper_base">
    <inertial>
      <origin rpy="0 0 0" xyz="0 0 0.0"/>
      <mass value="0.07"/>
      <inertia ixx="0.000010725" ixy="0.0" ixz="0.0" iyy="0.000014392" iyz="0.0" izz="0.000018517"/>
    </inertial>
    <visual>
      <geometry>
        <mesh filename="file:///home/rosdev/arm_ws/install/mycobot_description/share/mycobot_description/meshes/mycobot_280/gripper_base.dae"/>
      </geometry>
      <origin rpy="0 0 0" xyz="0.0 0.0 -0.012"/>
    </visual>
    <collision>
      <geometry>
        <box size="0.065 0.025 0.025"/>
      </geometry>
      <origin rpy="0 0 0" xyz="0.0 0.0 0.0"/>
    </collision>
  </link>
  <link name="gripper_left1">
    <inertial>
      <origin rpy="0 0 0" xyz="0 0 0.0"/>
      <mass value="0.007"/>
      <inertia ixx="1e-6" ixy="0.0" ixz="0.0" iyy="1e-6" iyz="0.0" izz="1e-6"/>
    </inertial>
    <visual>
      <geometry>
        <mesh filename="file:///home/rosdev/arm_ws/install/mycobot_description/share/mycobot_description/meshes/mycobot_280/gripper_left1.dae"/>
      </geometry>
      <origin rpy=" 0 0 0" xyz="0.039 -0.0133 -0.012 "/>
    </visual>
    <collision>
      <geometry>
        <box size="0.013 0.02 0.015"/>
      </geometry>
      <origin rpy=" 0 0 0" xyz="0.013 0.042 -0.010 "/>
    </collision>
  </link>
  <link name="gripper_left2">
    <inertial>
      <origin rpy="0 0 0" xyz="0 0 0.0"/>
      <mass value="0.007"/>
      <inertia ixx="1e-6" ixy="0.0" ixz="0.0" iyy="1e-6" iyz="0.0" izz="1e-6"/>
    </inertial>
    <visual>
      <geometry>
        <mesh filename="file:///home/rosdev/arm_ws/install/mycobot_description/share/mycobot_description/meshes/mycobot_280/gripper_left2.dae"/>
      </geometry>
      <origin rpy=" 0 0 0" xyz="0.005 -0.0195 -0.012 "/>
    </visual>
    <collision>
      <geometry>
        <box size="0.02 0.02 0.02"/>
      </geometry>
      <origin rpy=" 0 0 0" xyz="-0.025 0.0 -0.010 "/>
    </collision>
  </link>
  <link name="gripper_left3">
    <inertial>
      <origin rpy="0 0 0" xyz="0 0 0.0"/>
      <mass value="0.007"/>
      <inertia ixx="1e-6" ixy="0.0" ixz="0.0" iyy="1e-6" iyz="0.0" izz="1e-6"/>
    </inertial>
    <visual>
      <geometry>
        <mesh filename="file:///home/rosdev/arm_ws/install/mycobot_description/share/mycobot_description/meshes/mycobot_280/gripper_left3.dae"/>
      </geometry>
      <origin rpy=" 0 0 0" xyz="0.012 0.0025 -0.012 "/>
    </visual>
    <collision>
      <geometry>
        <box size="0.01 0.01 0.01"/>
      </geometry>
      <origin rpy=" 0 0 0" xyz="-0.014 0.005 0.005 "/>
    </collision>
  </link>
  <link name="gripper_right1">
    <inertial>
      <origin rpy="0 0 0" xyz="0 0 0.0"/>
      <mass value="0.007"/>
      <inertia ixx="1e-6" ixy="0.0" ixz="0.0" iyy="1e-6" iyz="0.0" izz="1e-6"/>
    </inertial>
    <visual>
      <geometry>
        <mesh filename="file:///home/rosdev/arm_ws/install/mycobot_description/share/mycobot_description/meshes/mycobot_280/gripper_right1.dae"/>
      </geometry>
      <origin rpy=" 0 0 0" xyz="-0.039 -0.0133 -0.012 "/>
    </visual>
    <collision>
      <geometry>
        <box size="0.013 0.02 0.015"/>
      </geometry>
      <origin rpy=" 0 0 0" xyz="-0.013 0.042 -0.010 "/>
    </collision>
  </link>
  <link name="gripper_right2">
    <inertial>
      <origin rpy="0 0 0" xyz="0 0 0.0"/>
      <mass value="0.007"/>
      <inertia ixx="1e-6" ixy="0.0" ixz="0.0" iyy="1e-6" iyz="0.0" izz="1e-6"/>
    </inertial>
    <visual>
      <geometry>
        <mesh filename="file:///home/rosdev/arm_ws/install/mycobot_description/share/mycobot_description/meshes/mycobot_280/gripper_right2.dae"/>
      </geometry>
      <origin rpy=" 0 0 0" xyz="-0.005 -0.0195 -0.012 "/>
    </visual>
    <collision>
      <geometry>
        <box size="0.02 0.02 0.02"/>
      </geometry>
      <origin rpy=" 0 0 0" xyz="0.025 0.0 -0.010 "/>
    </collision>
  </link>
  <link name="gripper_right3">
    <inertial>
      <origin rpy="0 0 0" xyz="0 0 0.0"/>
      <mass value="0.007"/>
      <inertia ixx="1e-6" ixy="0.0" ixz="0.0" iyy="1e-6" iyz="0.0" izz="1e-6"/>
    </inertial>
    <visual>
      <geometry>
        <mesh filename="file:///home/rosdev/arm_ws/install/mycobot_description/share/mycobot_description/meshes/mycobot_280/gripper_right3.dae"/>
      </geometry>
      <origin rpy=" 0 0 0" xyz="-0.012 0.0025 -0.012 "/>
    </visual>
    <collision>
      <geometry>
        <box size="0.01 0.01 0.01"/>
      </geometry>
      <origin rpy=" 0 0 0" xyz="0.014 0.005 0.005 "/>
    </collision>
  </link>
  <gazebo reference="base_link">
    <visual>
      <material>
        <ambient>0.5 0.5 0.5 1</ambient>
        <diffuse>0.5 0.5 0.5 1</diffuse>
        <specular>0.5 0.5 0.5 1</specular>
      </material>
    </visual>
  </gazebo>
  <gazebo reference="link1">
    <visual>
      <material>
        <ambient>0.5 0.5 0.5 1</ambient>
        <diffuse>0.5 0.5 0.5 1</diffuse>
        <specular>0.5 0.5 0.5 1</specular>
      </material>
    </visual>
  </gazebo>
  <gazebo reference="link2">
    <visual>
      <material>
        <ambient>1 1 1 1</ambient>
        <diffuse>1 1 1 1</diffuse>
        <specular>1 1 1 1</specular>
      </material>
    </visual>
  </gazebo>
  <gazebo reference="link3">
    <visual>
      <material>
        <ambient>1 1 1 1</ambient>
        <diffuse>1 1 1 1</diffuse>
        <specular>1 1 1 1</specular>
      </material>
    </visual>
  </gazebo>
  <gazebo reference="link4">
    <visual>
      <material>
        <ambient>1 1 1 1</ambient>
        <diffuse>1 1 1 1</diffuse>
        <specular>1 1 1 1</specular>
      </material>
    </visual>
  </gazebo>
  <gazebo reference="link5">
    <visual>
      <material>
        <ambient>1 1 1 1</ambient>
        <diffuse>1 1 1 1</diffuse>
        <specular>1 1 1 1</specular>
      </material>
    </visual>
  </gazebo>
  <gazebo reference="link6">
    <visual>
      <material>
        <ambient>1 1 1 1</ambient>
        <diffuse>1 1 1 1</diffuse>
        <specular>1 1 1 1</specular>
      </material>
    </visual>
  </gazebo>
  <gazebo reference="link6_flange">
    <visual>
      <material>
        <ambient>0.5 0.5 0.5 1</ambient>
        <diffuse>0.5 0.5 0.5 1</diffuse>
        <specular>0.5 0.5 0.5 1</specular>
      </material>
    </visual>
  </gazebo>
  <gazebo reference="gripper_base">
    <visual>
      <material>
        <ambient>1 1 1 1</ambient>
        <diffuse>1 1 1 1</diffuse>
        <specular>1 1 1 1</specular>
      </material>
    </visual>
  </gazebo>
  <joint name="virtual_joint" type="fixed">
    <parent link="world"/>
    <child link="base_link"/>
    <origin rpy="0 0 0" xyz="0 0 0"/>
  </joint>
  <joint name="base_link_to_link1" type="fixed">
    <parent link="base_link"/>
    <child link="link1"/>
    <origin rpy="0 0 0" xyz="0 0 0"/>
  </joint>
  <joint name="link1_to_link2" type="revolute">
    <axis xyz="0 0 1"/>
    <limit effort="56.0" lower="-2.879793" upper="2.879793" velocity="2.792527"/>
    <parent link="link1"/>
    <child link="link2"/>
    <origin rpy="0 0 1.5707963267948966" xyz="0 0 0.13156"/>
    <dynamics damping="0.0" friction="0.0"/>
  </joint>
  <joint name="link2_to_link3" type="revolute">
    <axis xyz="0 0 1"/>
    <limit effort="56.0" lower="-2.879793" upper="2.879793" velocity="2.792527"/>
    <parent link="link2"/>
    <child link="link3"/>
    <origin rpy="0 1.5707963267948966 -1.5707963267948966" xyz="0 0 -0.001"/>
    <dynamics damping="0.0" friction="0.0"/>
  </joint>
  <joint name="link3_to_link4" type="revolute">
    <axis xyz=" 0 0 1"/>
    <limit effort="56.0" lower="-2.879793" upper="2.879793" velocity="2.792527"/>
    <parent link="link3"/>
    <child link="link4"/>
    <origin rpy="0 0 0" xyz="-0.1104 0 0   "/>
    <dynamics damping="0.0" friction="0.0"/>
  </joint>
  <joint name="link4_to_link5" type="revolute">
    <axis xyz=" 0 0 1"/>
    <limit effort="56.0" lower="-2.879793" upper="2.879793" velocity="2.792527"/>
    <parent link="link4"/>
    <child link="link5"/>
    <origin rpy="0 0 -1.5707963267948966" xyz="-0.096 0 0.06062"/>
    <dynamics damping="0.0" friction="0.0"/>
  </joint>
  <joint name="link5_to_link6" type="revolute">
    <axis xyz=" 0 0 1"/>
    <limit effort="56.0" lower="-2.879793" upper="2.879793" velocity="2.792527"/>
    <parent link="link5"/>
    <child link="link6"/>
    <origin rpy="1.5707963267948966 -1.5707963267948966 0" xyz="0 -0.07318 0"/>
    <dynamics damping="0.0" friction="0.0"/>
  </joint>
  <joint name="link6_to_link6flange" type="revolute">
    <axis xyz=" 0 0 1"/>
    <limit effort="56.0" lower="-3.05" upper="3.05" velocity="2.792527"/>
    <parent link="link6"/>
    <child link="link6_flange"/>
    <origin rpy="-1.5707963267948966 0 0" xyz="0 0.0456 0"/>
    <dynamics damping="0.0" friction="0.0"/>
  </joint>
  <joint name="link6flange_to_gripper_base" type="fixed">
    <parent link="link6_flange"/>
    <child link="gripper_base"/>
    <origin rpy="1.579 0 0" xyz="0 0 0.034"/>
  </joint>
  <joint name="gripper_controller" type="revolute">
    <axis xyz="0 0 1"/>
    <limit effort="56.0" lower="-0.7" upper="0.15" velocity="2.792527"/>
    <parent link="gripper_base"/>
    <child link="gripper_left3"/>
    <origin rpy="0 0 0" xyz="-0.012 0.005 0"/>
    <dynamics damping="0.0" friction="0.0"/>
  </joint>
  <joint name="gripper_base_to_gripper_left2" type="revolute">
    <axis xyz="0 0 1"/>
    <limit effort="56.0" lower="-0.8" upper="0.5" velocity="2.792527"/>
    <parent link="gripper_base"/>
    <child link="gripper_left2"/>
    <origin rpy="0 0 0" xyz="-0.005 0.027 0"/>
    <mimic joint="gripper_controller" multiplier="1.0" offset="0"/>
    <dynamics damping="0.0" friction="0.0"/>
  </joint>
  <joint name="gripper_left3_to_gripper_left1" type="revolute">
    <axis xyz="0 0 1"/>
    <limit effort="56.0" lower="-0.5" upper="0.5" velocity="2.792527"/>
    <parent link="gripper_left3"/>
    <child link="gripper_left1"/>
    <origin rpy="0 0 0" xyz="-0.027 0.016 0"/>
    <mimic joint="gripper_controller" multiplier="-1.0" offset="0"/>
    <dynamics damping="0.0" friction="0.0"/>
  </joint>
  <joint name="gripper_base_to_gripper_right3" type="revolute">
    <axis xyz="0 0 1"/>
    <limit effort="56.0" lower="-0.15" upper="0.7" velocity="2.792527"/>
    <parent link="gripper_base"/>
    <child link="gripper_right3"/>
    <origin rpy="0 0 0" xyz="0.012 0.005 0"/>
    <mimic joint="gripper_controller" multiplier="-1.0" offset="0"/>
    <dynamics damping="0.0" friction="0.0"/>
  </joint>
  <joint name="gripper_base_to_gripper_right2" type="revolute">
    <axis xyz="0 0 1"/>
    <limit effort="56.0" lower="-0.5" upper="0.8" velocity="2.792527"/>
    <parent link="gripper_base"/>
    <child link="gripper_right2"/>
    <origin rpy="0 0 0" xyz="0.005 0.027 0"/>
    <mimic joint="gripper_controller" multiplier="-1.0" offset="0"/>
    <dynamics damping="0.0" friction="0.0"/>
  </joint>
  <joint name="gripper_right3_to_gripper_right1" type="revolute">
    <axis xyz="0 0 1"/>
    <limit effort="56.0" lower="-0.5" upper="0.5" velocity="2.792527"/>
    <parent link="gripper_right3"/>
    <child link="gripper_right1"/>
    <origin rpy="0 0 0" xyz="0.027 0.016 0"/>
    <mimic joint="gripper_controller" multiplier="1.0" offset="0"/>
    <dynamics damping="0.0" friction="0.0"/>
  </joint>
</robot>
